affected_purls:
- pkg:pypi/django@1.11
- pkg:pypi/django@1.11.1
- pkg:pypi/django@1.11.10
- pkg:pypi/django@1.11.11
- pkg:pypi/django@1.11.12
- pkg:pypi/django@1.11.13
- pkg:pypi/django@1.11.14
- pkg:pypi/django@1.11.15
- pkg:pypi/django@1.11.16
- pkg:pypi/django@1.11.17
- pkg:pypi/django@1.11.18
- pkg:pypi/django@1.11.2
- pkg:pypi/django@1.11.20
- pkg:pypi/django@1.11.21
- pkg:pypi/django@1.11.22
- pkg:pypi/django@1.11.3
- pkg:pypi/django@1.11.4
- pkg:pypi/django@1.11.5
- pkg:pypi/django@1.11.6
- pkg:pypi/django@1.11.7
- pkg:pypi/django@1.11.8
- pkg:pypi/django@1.11.9
- pkg:pypi/django@2.1
- pkg:pypi/django@2.1.1
- pkg:pypi/django@2.1.10
- pkg:pypi/django@2.1.2
- pkg:pypi/django@2.1.3
- pkg:pypi/django@2.1.4
- pkg:pypi/django@2.1.5
- pkg:pypi/django@2.1.7
- pkg:pypi/django@2.1.8
- pkg:pypi/django@2.1.9
- pkg:pypi/django@2.2
- pkg:pypi/django@2.2.1
- pkg:pypi/django@2.2.2
- pkg:pypi/django@2.2.3
aliases:
- CVE-2019-14235
- GHSA-v9qg-3j8p-r63v
fixed_purl:
- pkg:deb/debian/python-django@1:1.11.23-1~deb10u1?distro=sid
- pkg:deb/debian/python-django@1:1.11.29-1~deb10u1?distro=sid
- pkg:deb/debian/python-django@2:2.2.28-1~deb11u1?distro=sid
- pkg:deb/debian/python-django@2:2.2.4-1?distro=sid
- pkg:deb/debian/python-django@3:3.2.19-1?distro=sid
- pkg:pypi/django@1.11.23
- pkg:pypi/django@2.1.11
- pkg:pypi/django@2.2.4
references:
- id: 147329
  reference_id: ''
  url: http://lists.opensuse.org/opensuse-security-announce/2019-08/msg00006.html
- id: 147330
  reference_id: ''
  url: http://lists.opensuse.org/opensuse-security-announce/2019-08/msg00025.html
- id: 147478
  reference_id: ''
  url: https://docs.djangoproject.com/en/dev/releases/security/
- id: 147883
  reference_id: ''
  url: https://groups.google.com/forum/#!topic/django-announce/jIoju2-KLDs
- id: 147885
  reference_id: ''
  url: https://lists.fedoraproject.org/archives/list/package-announce@lists.fedoraproject.org/message/STVX7X7IDWAH5SKE6MBMY3TEI6ZODBTK/
- id: 147886
  reference_id: ''
  url: https://seclists.org/bugtraq/2019/Aug/15
- id: 147887
  reference_id: ''
  url: https://security.gentoo.org/glsa/202004-17
- id: 147888
  reference_id: ''
  url: https://security.netapp.com/advisory/ntap-20190828-0002/
- id: 147889
  reference_id: ''
  url: https://www.debian.org/security/2019/dsa-4498
- id: 147884
  reference_id: ''
  url: https://www.djangoproject.com/weblog/2019/aug/01/security-releases/
- id: 128615
  reference_id: '934026'
  url: https://bugs.debian.org/cgi-bin/bugreport.cgi?bug=934026
- id: 147897
  reference_id: CVE-2019-14235
  url: https://nvd.nist.gov/vuln/detail/CVE-2019-14235
- id: 147898
  reference_id: GHSA-v9qg-3j8p-r63v
  url: https://github.com/advisories/GHSA-v9qg-3j8p-r63v
severities:
- id: 20830
  reference_id: 147898
  scoring_elements: ''
  scoring_system: cvssv3.1_qr
  value: HIGH
summary: An issue was discovered in Django 1.11.x before 1.11.23, 2.1.x before 2.1.11,
  and 2.2.x before 2.2.4. If passed certain inputs, django.utils.encoding.uri_to_iri
  could lead to significant memory usage due to a recursion when repercent-encoding
  invalid UTF-8 octet sequences.
vulnerability_id: VCID-cw9e-r6k8-aaaf
weaknesses: []
