affected_purls:
- pkg:pypi/django@2.2
- pkg:pypi/django@2.2.1
- pkg:pypi/django@2.2.10
- pkg:pypi/django@2.2.11
- pkg:pypi/django@2.2.12
- pkg:pypi/django@2.2.13
- pkg:pypi/django@2.2.14
- pkg:pypi/django@2.2.15
- pkg:pypi/django@2.2.2
- pkg:pypi/django@2.2.3
- pkg:pypi/django@2.2.4
- pkg:pypi/django@2.2.5
- pkg:pypi/django@2.2.6
- pkg:pypi/django@2.2.7
- pkg:pypi/django@2.2.8
- pkg:pypi/django@2.2.9
- pkg:pypi/django@3.0
- pkg:pypi/django@3.0.1
- pkg:pypi/django@3.0.2
- pkg:pypi/django@3.0.3
- pkg:pypi/django@3.0.4
- pkg:pypi/django@3.0.5
- pkg:pypi/django@3.0.6
- pkg:pypi/django@3.0.7
- pkg:pypi/django@3.0.8
- pkg:pypi/django@3.0.9
- pkg:pypi/django@3.1
aliases:
- CVE-2020-24583
- GHSA-m6gj-h9gm-gw44
fixed_purl:
- pkg:deb/debian/python-django@1:1.11.29-1~deb10u1?distro=sid
- pkg:deb/debian/python-django@1:1.11.29-1%2Bdeb10u2?distro=sid
- pkg:deb/debian/python-django@2:2.2.16-1?distro=sid
- pkg:deb/debian/python-django@2:2.2.28-1~deb11u1?distro=sid
- pkg:deb/debian/python-django@3:3.2.19-1?distro=sid
- pkg:pypi/django@2.2.16
- pkg:pypi/django@3.0.10
- pkg:pypi/django@3.0a1
- pkg:pypi/django@3.1.1
- pkg:pypi/django@3.1a1
references:
- id: 147478
  reference_id: ''
  url: https://docs.djangoproject.com/en/dev/releases/security/
- id: 152716
  reference_id: ''
  url: https://github.com/django/django/commit/8d7271578d7b153435b40fe40236ebec43cbf1b9
- id: 152717
  reference_id: ''
  url: https://groups.google.com/forum/#!topic/django-announce/Gdqn58RqIDM
- id: 152718
  reference_id: ''
  url: https://groups.google.com/forum/#!topic/django-announce/zFCMdgUnutU
- id: 152719
  reference_id: ''
  url: https://lists.fedoraproject.org/archives/list/package-announce@lists.fedoraproject.org/message/F2ZHO3GZCJMP3DDTXCNVFV6ED3W64NAU/
- id: 152720
  reference_id: ''
  url: https://lists.fedoraproject.org/archives/list/package-announce@lists.fedoraproject.org/message/OLGFFLMF3X6USMJD7V5F5P4K2WVUTO3T/
- id: 152721
  reference_id: ''
  url: https://lists.fedoraproject.org/archives/list/package-announce@lists.fedoraproject.org/message/ZCRPQCBTV3RZHKVZ6K6QOAANPRZQD3GI/
- id: 152722
  reference_id: ''
  url: https://security.netapp.com/advisory/ntap-20200918-0004/
- id: 152723
  reference_id: ''
  url: https://usn.ubuntu.com/4479-1/
- id: 152724
  reference_id: ''
  url: https://www.djangoproject.com/weblog/2020/sep/01/security-releases/
- id: 152725
  reference_id: ''
  url: https://www.openwall.com/lists/oss-security/2020/09/01/2
- id: 134377
  reference_id: ''
  url: https://www.oracle.com/security-alerts/cpujan2021.html
- id: 129287
  reference_id: '969367'
  url: https://bugs.debian.org/cgi-bin/bugreport.cgi?bug=969367
- id: 152715
  reference_id: CVE-2020-24583
  url: https://nvd.nist.gov/vuln/detail/CVE-2020-24583
- id: 152726
  reference_id: GHSA-m6gj-h9gm-gw44
  url: https://github.com/advisories/GHSA-m6gj-h9gm-gw44
severities:
- id: 21800
  reference_id: 152726
  scoring_elements: ''
  scoring_system: cvssv3.1_qr
  value: HIGH
summary: An issue was discovered in Django 2.2 before 2.2.16, 3.0 before 3.0.10, and
  3.1 before 3.1.1 (when Python 3.7+ is used). FILE_UPLOAD_DIRECTORY_PERMISSIONS mode
  was not applied to intermediate-level directories created in the process of uploading
  files. It was also not applied to intermediate-level collected static directories
  when using the collectstatic management command.
vulnerability_id: VCID-fn1u-dccv-aaaf
weaknesses: []
